Workbook

Sheet Raw Data
A1: 📊 Personal Finance — Raw Transaction Data
A2: Date | B2: Month | C2: Income Source | D2: Expense Category | E2: Expense Type | F2: Payment Mode | G2: Amount | H2: Indicator | I2: Savings | J2: Budget Allocated | K2: Budget Remaining | L2: Notes
A3: 03-01-2026 | B3: Jan | C3: Salary | E3: Variable | F3: UPI | G3: 18982 | H3: Income | J3: 10000 | K3: =IF(H3="Expense",J3-G3,"N/A") -> N/A
A4: 04-01-2026 | B4: Jan | D4: Travel | E4: Variable | F4: Bank | G4: 5977 | H4: Expense | J4: 10000 | K4: =IF(H4="Expense",J4-G4,"N/A") -> 4023
A5: 05-01-2026 | B5: Jan | D5: Food | E5: Variable | F5: Credit Card | G5: 7197 | H5: Expense | J5: 10000 | K5: =IF(H5="Expense",J5-G5,"N/A") -> 2803
A6: 06-01-2026 | B6: Jan | C6: Business | E6: Variable | F6: Cash | G6: 7664 | H6: Income | J6: 10000 | K6: =IF(H6="Expense",J6-G6,"N/A") -> N/A
A7: 07-01-2026 | B7: Jan | D7: Shopping | E7: Variable | F7: Cash | G7: 7798 | H7: Expense | J7: 10000 | K7: =IF(H7="Expense",J7-G7,"N/A") -> 2202
A8: 08-01-2026 | B8: Jan | D8: Travel | E8: Variable | F8: Credit Card | G8: 3186 | H8: Expense | J8: 10000 | K8: =IF(H8="Expense",J8-G8,"N/A") -> 6814
A9: 09-01-2026 | B9: Jan | C9: Business | E9: Variable | F9: Credit Card | G9: 23666 | H9: Income | J9: 10000 | K9: =IF(H9="Expense",J9-G9,"N/A") -> N/A
A10: 10-01-2026 | B10: Jan | C10: Business | E10: Variable | F10: Cash | G10: 23532 | H10: Income | J10: 10000 | K10: =IF(H10="Expense",J10-G10,"N/A") -> N/A
A11: 11-01-2026 | B11: Jan | D11: Shopping | E11: Variable | F11: Bank | G11: 2329 | H11: Expense | J11: 10000 | K11: =IF(H11="Expense",J11-G11,"N/A") -> 7671
A12: 12-01-2026 | B12: Jan | C12: Salary | E12: Variable | F12: Cash | G12: 7171 | H12: Income | J12: 10000 | K12: =IF(H12="Expense",J12-G12,"N/A") -> N/A
A13: 13-01-2026 | B13: Jan | C13: Salary | E13: Variable | F13: Bank | G13: 11356 | H13: Income | J13: 10000 | K13: =IF(H13="Expense",J13-G13,"N/A") -> N/A
A14: 14-01-2026 | B14: Jan | C14: Freelance | E14: Variable | F14: Cash | G14: 14668 | H14: Income | J14: 10000 | K14: =IF(H14="Expense",J14-G14,"N/A") -> N/A
A15: 15-01-2026 | B15: Jan | D15: EMI | E15: Variable | F15: Bank | G15: 3070 | H15: Expense | J15: 10000 | K15: =IF(H15="Expense",J15-G15,"N/A") -> 6930
A16: 16-01-2026 | B16: Jan | D16: Bills | E16: Variable | F16: UPI | G16: 1086 | H16: Expense | J16: 10000 | K16: =IF(H16="Expense",J16-G16,"N/A") -> 8914
A17: 17-01-2026 | B17: Jan | C17: Business | E17: Variable | F17: Credit Card | G17: 9129 | H17: Income | J17: 10000 | K17: =IF(H17="Expense",J17-G17,"N/A") -> N/A
A18: 18-01-2026 | B18: Jan | D18: Bills | E18: Variable | F18: UPI | G18: 3572 | H18: Expense | J18: 10000 | K18: =IF(H18="Expense",J18-G18,"N/A") -> 6428
A19: 19-01-2026 | B19: Jan | D19: Rent | E19: Fixed | F19: UPI | G19: 3430 | H19: Expense | J19: 10000 | K19: =IF(H19="Expense",J19-G19,"N/A") -> 6570
A20: 20-01-2026 | B20: Jan | D20: Rent | E20: Fixed | F20: Cash | G20: 6284 | H20: Expense | J20: 10000 | K20: =IF(H20="Expense",J20-G20,"N/A") -> 3716
A21: 21-01-2026 | B21: Jan | D21: Travel | E21: Variable | F21: Credit Card | G21: 4494 | H21: Expense | J21: 10000 | K21: =IF(H21="Expense",J21-G21,"N/A") -> 5506
A22: 22-01-2026 | B22: Jan | D22: Travel | E22: Variable | F22: Cash | G22: 4555 | H22: Expense | J22: 10000 | K22: =IF(H22="Expense",J22-G22,"N/A") -> 5445
A23: 23-01-2026 | B23: Jan | D23: Shopping | E23: Variable | F23: Bank | G23: 3025 | H23: Expense | J23: 10000 | K23: =IF(H23="Expense",J23-G23,"N/A") -> 6975
A24: 24-01-2026 | B24: Jan | D24: Food | E24: Variable | F24: Credit Card | G24: 5297 | H24: Expense | J24: 10000 | K24: =IF(H24="Expense",J24-G24,"N/A") -> 4703
A25: 25-01-2026 | B25: Jan | C25: Freelance | E25: Variable | F25: Credit Card | G25: 22310 | H25: Income | J25: 10000 | K25: =IF(H25="Expense",J25-G25,"N/A") -> N/A
A26: 26-01-2026 | B26: Jan | D26: Food | E26: Variable | F26: Cash | G26: 8876 | H26: Expense | J26: 10000 | K26: =IF(H26="Expense",J26-G26,"N/A") -> 1124
A27: 27-01-2026 | B27: Jan | C27: Business | E27: Variable | F27: Bank | G27: 23790 | H27: Income | J27: 10000 | K27: =IF(H27="Expense",J27-G27,"N/A") -> N/A
A28: 28-01-2026 | B28: Jan | D28: Rent | E28: Fixed | F28: Bank | G28: 4667 | H28: Expense | J28: 10000 | K28: =IF(H28="Expense",J28-G28,"N/A") -> 5333
A29: 29-01-2026 | B29: Jan | C29: Salary | E29: Variable | F29: Credit Card | G29: 26898 | H29: Income | J29: 10000 | K29: =IF(H29="Expense",J29-G29,"N/A") -> N/A
A30: 30-01-2026 | B30: Jan | C30: Salary | E30: Variable | F30: Cash | G30: 17086 | H30: Income | J30: 10000 | K30: =IF(H30="Expense",J30-G30,"N/A") -> N/A
A31: 31-01-2026 | B31: Jan | D31: Food | E31: Variable | F31: Cash | G31: 4431 | H31: Expense | J31: 10000 | K31: =IF(H31="Expense",J31-G31,"N/A") -> 5569
A32: 01-02-2026 | B32: Feb | C32: Salary | E32: Variable | F32: Cash | G32: 10480 | H32: Income | J32: 10000 | K32: =IF(H32="Expense",J32-G32,"N/A") -> N/A
A33: 02-02-2026 | B33: Feb | C33: Business | E33: Variable | F33: Credit Card | G33: 28674 | H33: Income | J33: 10000 | K33: =IF(H33="Expense",J33-G33,"N/A") -> N/A
A34: 03-02-2026 | B34: Feb | C34: Freelance | E34: Variable | F34: Cash | G34: 20894 | H34: Income | J34: 10000 | K34: =IF(H34="Expense",J34-G34,"N/A") -> N/A
A35: 04-02-2026 | B35: Feb | C35: Business | E35: Variable | F35: Bank | G35: 25982 | H35: Income | J35: 10000 | K35: =IF(H35="Expense",J35-G35,"N/A") -> N/A
A36: 05-02-2026 | B36: Feb | C36: Business | E36: Variable | F36: Cash | G36: 6102 | H36: Income | J36: 10000 | K36: =IF(H36="Expense",J36-G36,"N/A") -> N/A
A37: 06-02-2026 | B37: Feb | D37: Rent | E37: Fixed | F37: Credit Card | G37: 4276 | H37: Expense | J37: 10000 | K37: =IF(H37="Expense",J37-G37,"N/A") -> 5724
A38: 07-02-2026 | B38: Feb | C38: Salary | E38: Variable | F38: Cash | G38: 15498 | H38: Income | J38: 10000 | K38: =IF(H38="Expense",J38-G38,"N/A") -> N/A
A39: 08-02-2026 | B39: Feb | D39: Rent | E39: Fixed | F39: Credit Card | G39: 3030 | H39: Expense | J39: 10000 | K39: =IF(H39="Expense",J39-G39,"N/A") -> 6970
A40: 09-02-2026 | B40: Feb | C40: Business | E40: Variable | F40: UPI | G40: 15122 | H40: Income | J40: 10000 | K40: =IF(H40="Expense",J40-G40,"N/A") -> N/A
...

Sheet Cleaned Data

Sheet Budget Planning
A1: 🎯 Budget Planning & Tracking
A2: Category | B2: Monthly Budget | C2: Actual Spend | D2: Variance | E2: Status
A3: Food | B3: 10000 | C3: =SUMIFS('Raw Data'!G:G,'Raw Data'!D:D,"Food") -> 46266 | D3: =B3-C3 -> -36266 | E3: =IF(D3>=0,"✅ Under Budget","⚠️ Over Budget") -> ⚠️ Over Budget
A4: Rent | B4: 10000 | C4: =SUMIFS('Raw Data'!G:G,'Raw Data'!D:D,"Rent") -> 49757 | D4: =B4-C4 -> -39757 | E4: =IF(D4>=0,"✅ Under Budget","⚠️ Over Budget") -> ⚠️ Over Budget
A5: Travel | B5: 10000 | C5: =SUMIFS('Raw Data'!G:G,'Raw Data'!D:D,"Travel") -> 48174 | D5: =B5-C5 -> -38174 | E5: =IF(D5>=0,"✅ Under Budget","⚠️ Over Budget") -> ⚠️ Over Budget
A6: Shopping | B6: 10000 | C6: =SUMIFS('Raw Data'!G:G,'Raw Data'!D:D,"Shopping") -> 47042 | D6: =B6-C6 -> -37042 | E6: =IF(D6>=0,"✅ Under Budget","⚠️ Over Budget") -> ⚠️ Over Budget
A7: EMI | B7: 10000 | C7: =SUMIFS('Raw Data'!G:G,'Raw Data'!D:D,"EMI") -> 43059 | D7: =B7-C7 -> -33059 | E7: =IF(D7>=0,"✅ Under Budget","⚠️ Over Budget") -> ⚠️ Over Budget
A8: Bills | B8: 10000 | C8: =SUMIFS('Raw Data'!G:G,'Raw Data'!D:D,"Bills") -> 35163 | D8: =B8-C8 -> -25163 | E8: =IF(D8>=0,"✅ Under Budget","⚠️ Over Budget") -> ⚠️ Over Budget
A9: TOTAL | B9: =SUM(B3:B8) -> 60000 | C9: =SUM(C3:C8) -> 269461 | D9: =SUM(D3:D8) -> -209461 | E9: =IF(D9>=0,"✅ Under Budget","⚠️ Over Budget") -> ⚠️ Over Budget

Sheet KPI Summary
A1: 💰 KPI Summary Dashboard
A2: Key Performance Indicators — Personal Finance FY 2026
A4: 💵 Total Income
A5: =SUMIFS('Raw Data'!G:G,'Raw Data'!H:H,"Income") -> 876368 | C5: 💸 Total Expense
C6: =SUMIFS('Raw Data'!G:G,'Raw Data'!H:H,"Expense") -> 269461 | E6: 📈 Net Savings
A7: 💹 Savings Rate | C7: 📅 Avg Monthly Savings | E7: 🏦 Total Transactions
A8: =IFERROR(B5/B4,0) -> 0 | C8: =IFERROR(B6/4,0) -> 0 | E8: =COUNTA('Raw Data'!H3:H102)-COUNTBLANK('Raw Data'!H3:H102) -> 100

Sheet Dashboard
A1: 💼 PERSONAL FINANCE DASHBOARD | FY 2026
A2: Powered by Real Transaction Data • Jan – Apr 2026 • All amounts in INR (₹)
A4: 💵 TOTAL INCOME | D4: 💸 TOTAL EXPENSE | G4: 📈 NET SAVINGS | J4: 💹 SAVINGS RATE | M4: 🏦 TRANSACTIONS
A5: ='KPI Summary'!B5 -> 0 | D5: ='KPI Summary'!D5 -> 0 | G5: ='KPI Summary'!F5 -> 0 | J5: ='KPI Summary'!B8 -> 0 | M5: ='KPI Summary'!F8 -> 0
A10: 📅 MONTHLY BREAKDOWN | I10: 📊 EXPENSE BY CATEGORY
A11: Month | B11: Income (₹) | C11: Expense (₹) | D11: Net Savings (₹) | E11: Savings Rate | F11: vs Prev Month | I11: Category | J11: Amount (₹) | K11: % Share | L11: Budget (₹) | M11: Variance (₹) | N11: Status
A12: Jan | B12: ='Monthly Analysis'!B3 -> 206252 | C12: ='Monthly Analysis'!C3 -> 79274 | D12: ='Monthly Analysis'!D3 -> 126978 | E12: ='Monthly Analysis'!E3 -> 0.61564494 | F12: =IF(12>12,D12-D11,"--") -> -- | I12: Food | J12: ='Monthly Analysis'!H3 -> 46266 | K12: ='Monthly Analysis'!I3 -> 0.17169832 | L12: ='Budget Planning'!B3 -> 10000 | M12: ='Budget Planning'!D3 -> -36266 | N12: =IF(M12>=0,"✅ OK","⚠️ Over") -> ⚠️ Over
A13: Feb | B13: ='Monthly Analysis'!B4 -> 310740 | C13: ='Monthly Analysis'!C4 -> 55650 | D13: ='Monthly Analysis'!D4 -> 255090 | E13: ='Monthly Analysis'!E4 -> 0.82091137 | F13: =IF(13>12,D13-D12,"--") -> 128112 | I13: Rent | J13: ='Monthly Analysis'!H4 -> 48174 | K13: ='Monthly Analysis'!I4 -> 0.17877912 | L13: ='Budget Planning'!B4 -> 10000 | M13: ='Budget Planning'!D4 -> -39757 | N13: =IF(M13>=0,"✅ OK","⚠️ Over") -> ⚠️ Over
A14: Mar | B14: ='Monthly Analysis'!B5 -> 225210 | C14: ='Monthly Analysis'!C5 -> 111140 | D14: ='Monthly Analysis'!D5 -> 114070 | E14: ='Monthly Analysis'!E5 -> 0.50650504 | F14: =IF(14>12,D14-D13,"--") -> -141020 | I14: Travel | J14: ='Monthly Analysis'!H5 -> 47042 | K14: ='Monthly Analysis'!I5 -> 0.17457814 | L14: ='Budget Planning'!B5 -> 10000 | M14: ='Budget Planning'!D5 -> -38174 | N14: =IF(M14>=0,"✅ OK","⚠️ Over") -> ⚠️ Over
A15: Apr | B15: ='Monthly Analysis'!B6 -> 134166 | C15: ='Monthly Analysis'!C6 -> 23397 | D15: ='Monthly Analysis'!D6 -> 110769 | E15: ='Monthly Analysis'!E6 -> 0.82561156 | F15: =IF(15>12,D15-D14,"--") -> -3301 | I15: Shopping | J15: ='Monthly Analysis'!H6 -> 49757 | K15: ='Monthly Analysis'!I6 -> 0.18465381 | L15: ='Budget Planning'!B6 -> 10000 | M15: ='Budget Planning'!D6 -> -37042 | N15: =IF(M15>=0,"✅ OK","⚠️ Over") -> ⚠️ Over
A16: TOTAL | B16: =SUM(B12:B15) -> 876368 | C16: =SUM(C12:C15) -> 269461 | D16: =SUM(D12:D15) -> 606907 | E16: =IFERROR(D16/B16,0) -> 0.69252529 | F16: — | I16: EMI | J16: ='Monthly Analysis'!H7 -> 43059 | K16: ='Monthly Analysis'!I7 -> 0.15979678 | L16: ='Budget Planning'!B7 -> 10000 | M16: ='Budget Planning'!D7 -> -33059 | N16: =IF(M16>=0,"✅ OK","⚠️ Over") -> ⚠️ Over
I17: Bills | J17: ='Monthly Analysis'!H8 -> 35163 | K17: ='Monthly Analysis'!I8 -> 0.13049384 | L17: ='Budget Planning'!B8 -> 10000 | M17: ='Budget Planning'!D8 -> -25163 | N17: =IF(M17>=0,"✅ OK","⚠️ Over") -> ⚠️ Over
I18: TOTAL | J18: =SUM(J12:J17) -> 269461 | K18: 100.0% | L18: ='Budget Planning'!B9 -> 60000 | M18: =IFERROR(L18-J18,0) -> -209461
A20: 🧠 KEY INSIGHTS & ANALYSIS
A21: 💡 Highest Expense | C21: Rent is the largest single expense category, accounting for ~18% of total spend.
A22: 📉 March Alert | C22: March had the highest expenses (₹1,11,140). Monitor recurring costs that month.
A23: 🏆 Best Month | C23: April had the best savings performance with the lowest expense-to-income ratio.
A24: 💰 Income Mix | C24: Income is well-diversified: Salary (37%), Business (36%), Freelance (27%).
A25: 🎯 Savings Target | C25: Current savings rate exceeds 69% — significantly above the recommended 20% benchmark.
A26: ⚠️ Action Item | C26: Shopping and Travel expenses combined equal ~35% of total spend. Review discretionary spend.

Sheet Monthly Analysis
A1: 📅 Monthly Income vs Expense Analysis
A2: Month | B2: Total Income | C2: Total Expense | D2: Net Savings | E2: Savings Rate | G2: Expense Category | H2: Total Amount | I2: % of Expenses | K2: Income Source | L2: Total Amount
A3: Jan | B3: =SUMIFS('Raw Data'!G:G,'Raw Data'!B:B,"Jan",'Raw Data'!H:H,"Income") -> 206252 | C3: =SUMIFS('Raw Data'!G:G,'Raw Data'!B:B,"Jan",'Raw Data'!H:H,"Expense") -> 79274 | D3: =B3-C3 -> 126978 | E3: =IFERROR(D3/B3,0) -> 0.61564494 | G3: Food | H3: =SUMIFS('Raw Data'!G:G,'Raw Data'!D:D,"Food") -> 46266 | I3: =IFERROR(H3/SUM(H3:H8),0) -> 0.17169832 | K3: Salary | L3: =SUMIFS('Raw Data'!G:G,'Raw Data'!C:C,"Salary") -> 317953
A4: Feb | B4: =SUMIFS('Raw Data'!G:G,'Raw Data'!B:B,"Feb",'Raw Data'!H:H,"Income") -> 310740 | C4: =SUMIFS('Raw Data'!G:G,'Raw Data'!B:B,"Feb",'Raw Data'!H:H,"Expense") -> 55650 | D4: =B4-C4 -> 255090 | E4: =IFERROR(D4/B4,0) -> 0.82091137 | G4: Travel | H4: =SUMIFS('Raw Data'!G:G,'Raw Data'!D:D,"Travel") -> 48174 | I4: =IFERROR(H4/SUM(H3:H8),0) -> 0.17877912 | K4: Business | L4: =SUMIFS('Raw Data'!G:G,'Raw Data'!C:C,"Business") -> 307424
A5: Mar | B5: =SUMIFS('Raw Data'!G:G,'Raw Data'!B:B,"Mar",'Raw Data'!H:H,"Income") -> 225210 | C5: =SUMIFS('Raw Data'!G:G,'Raw Data'!B:B,"Mar",'Raw Data'!H:H,"Expense") -> 111140 | D5: =B5-C5 -> 114070 | E5: =IFERROR(D5/B5,0) -> 0.50650504 | G5: Shopping | H5: =SUMIFS('Raw Data'!G:G,'Raw Data'!D:D,"Shopping") -> 47042 | I5: =IFERROR(H5/SUM(H3:H8),0) -> 0.17457814 | K5: Freelance | L5: =SUMIFS('Raw Data'!G:G,'Raw Data'!C:C,"Freelance") -> 250991
A6: Apr | B6: =SUMIFS('Raw Data'!G:G,'Raw Data'!B:B,"Apr",'Raw Data'!H:H,"Income") -> 134166 | C6: =SUMIFS('Raw Data'!G:G,'Raw Data'!B:B,"Apr",'Raw Data'!H:H,"Expense") -> 23397 | D6: =B6-C6 -> 110769 | E6: =IFERROR(D6/B6,0) -> 0.82561156 | G6: Rent | H6: =SUMIFS('Raw Data'!G:G,'Raw Data'!D:D,"Rent") -> 49757 | I6: =IFERROR(H6/SUM(H3:H8),0) -> 0.18465381
G7: EMI | H7: =SUMIFS('Raw Data'!G:G,'Raw Data'!D:D,"EMI") -> 43059 | I7: =IFERROR(H7/SUM(H3:H8),0) -> 0.15979678
G8: Bills | H8: =SUMIFS('Raw Data'!G:G,'Raw Data'!D:D,"Bills") -> 35163 | I8: =IFERROR(H8/SUM(H3:H8),0) -> 0.13049384
